---------------------------16050405012003: Can't connect to MySQL server on 'mariadb:3306' (-2 Name or service not known)Traceback (most recent call last):
  File "/usr/local/lib/python3.8/site-packages/mysql/connector/network.py", line 580, in open_connection
    addrinfos = socket.getaddrinfo(self.server_host,
  File "/usr/local/lib/python3.8/socket.py", line 918, in getaddrinfo
    for res in _socket.getaddrinfo(host, port, family, type, proto, flags):
socket.gaierror: [Errno -2] Name or service not known

During handling of the above exception, another exception occurred:

Traceback (most recent call last):
  File "./bot.py", line 75, in repeat_all_messages
    cor = core(message.from_user.id)
  File "/bot/core.py", line 13, in __init__
    self.db = SQLighter(telid=telid, idd=idd, logger=logger)  # Модуль подключения к базе данных
  File "/bot/sql.py", line 12, in __init__
    self.connection = mysql.connector.connect(
  File "/usr/local/lib/python3.8/site-packages/mysql/connector/__init__.py", line 271, in connect
    return MySQLConnection(*args, **kwargs)
  File "/usr/local/lib/python3.8/site-packages/mysql/connector/connection.py", line 107, in __init__
    self.connect(**kwargs)
  File "/usr/local/lib/python3.8/site-packages/mysql/connector/abstracts.py", line 985, in connect
    self._open_connection()
  File "/usr/local/lib/python3.8/site-packages/mysql/connector/connection.py", line 308, in _open_connection
    self._socket.open_connection()
  File "/usr/local/lib/python3.8/site-packages/mysql/connector/network.py", line 598, in open_connection
    raise errors.InterfaceError(
mysql.connector.errors.InterfaceError: 2003: Can't connect to MySQL server on 'mariadb:3306' (-2 Name or service not known)
---------------------------1605041911'<' not supported between instances of 'NoneType' and 'int'Traceback (most recent call last):
  File "./bot.py", line 90, in handle_edit
    users, data = cor.toall(message.text, message.message_id)
  File "/bot/core.py", line 141, in toall
    if self.user.get('admin')<1:
TypeError: '<' not supported between instances of 'NoneType' and 'int'
---------------------------1605042088local variable 'out' referenced before assignmentTraceback (most recent call last):
  File "./bot.py", line 92, in handle_edit
    sent_info = send(data=data, to=user)
  File "./bot.py", line 199, in send
    if type(out)==list:
UnboundLocalError: local variable 'out' referenced before assignment
---------------------------1605042211local variable 'out' referenced before assignmentTraceback (most recent call last):
  File "./bot.py", line 92, in handle_edit
    sent_info = send(data=data, to=user)
  File "./bot.py", line 199, in send
    out = bot.edit_message_text(text=mess,chat_id=to,message_id=messId)
UnboundLocalError: local variable 'out' referenced before assignment
---------------------------1605042251object of type 'NoneType' has no len()Traceback (most recent call last):
  File "./bot.py", line 90, in handle_edit
    users, data = cor.toall(message.text, message.message_id)
  File "/bot/core.py", line 145, in toall
    if mess is None or len(mess[1])==0: return {'mess': 'Not right format for command'}
TypeError: object of type 'NoneType' has no len()
---------------------------1605042302not enough values to unpack (expected 2, got 1)Traceback (most recent call last):
  File "./bot.py", line 90, in handle_edit
    users, data = cor.toall(message.text, message.message_id)
ValueError: not enough values to unpack (expected 2, got 1)
---------- 1605055669 ----------1054 (42S22): Unknown column 'id_user' in 'field list'Traceback (most recent call last):
  File "./bot.py", line 62, in handle_command
    cor.close(data=data,sent_info=sent_info,mode='command')
  File "/bot/core.py", line 56, in close
    self.log_save(mess=data.get('command',None),typ=1)
  File "/bot/core.py", line 64, in log_save
    self.db.log_add(typ=typ, message=mess)
  File "/bot/sql.py", line 229, in log_add
    return self.addToTable('users',
  File "/bot/sql.py", line 83, in addToTable
    self.cursor.execute("INSERT INTO " + table + field_text + " VALUES " + add_text)
  File "/usr/local/lib/python3.8/site-packages/mysql/connector/cursor.py", line 569, in execute
    self._handle_result(self._connection.cmd_query(stmt))
  File "/usr/local/lib/python3.8/site-packages/mysql/connector/connection.py", line 651, in cmd_query
    result = self._handle_result(self._send_cmd(ServerCmd.QUERY, query))
  File "/usr/local/lib/python3.8/site-packages/mysql/connector/connection.py", line 538, in _handle_result
    raise errors.get_exception(packet)
mysql.connector.errors.ProgrammingError: 1054 (42S22): Unknown column 'id_user' in 'field list'
---------- 1605056192 11/11/2020, 00:56:32 ----------COMMAND. mess = /famille;Command = famille;City = None;
1146 (42S02): Table 'deplacement_bot.log' doesn't existTraceback (most recent call last):
  File "./bot.py", line 63, in handle_command
    cor.close(data=data,sent_info=sent_info,mode='command')
  File "/bot/core.py", line 56, in close
    self.log_save(mess=data.get('command',None),typ=1)
  File "/bot/core.py", line 64, in log_save
    self.db.log_add(typ=typ, message=mess)
  File "/bot/sql.py", line 229, in log_add
    return self.addToTable('log',
  File "/bot/sql.py", line 83, in addToTable
    self.cursor.execute("INSERT INTO " + table + field_text + " VALUES " + add_text)
  File "/usr/local/lib/python3.8/site-packages/mysql/connector/cursor.py", line 569, in execute
    self._handle_result(self._connection.cmd_query(stmt))
  File "/usr/local/lib/python3.8/site-packages/mysql/connector/connection.py", line 651, in cmd_query
    result = self._handle_result(self._send_cmd(ServerCmd.QUERY, query))
  File "/usr/local/lib/python3.8/site-packages/mysql/connector/connection.py", line 538, in _handle_result
    raise errors.get_exception(packet)
mysql.connector.errors.ProgrammingError: 1146 (42S02): Table 'deplacement_bot.log' doesn't exist
